<!DOCTYPE html>
<html lang="en">
<head>
    <meta charset="UTF-8">
    <meta content="IE=edge" http-equiv="X-UA-Compatible">
    <meta content="width=device-width, initial-scale=1.0" name="viewport">
    <title>Title</title>
</head>
<body>
    <script>
        // 异常穿透：当使用 Promise 实例的 then 链式调用时，可以在最后使用 catch 捕获一个事变的回调。当前面任何操作出现了问题，都会传递到最后失败的回调中进行处理。
        const p = new Promise((resolve, reject) => {
            setTimeout(() => {
                resolve('用户数据');
            }, 1000);
        });
        p.then(value => {
            console.log('第一次请求成功', value);
            return new Promise((resolve, reject) => {
                setTimeout(() => {
                    reject('订单数据');
                }, 1000);
            });
        }).then(value => {
            console.log('第二次请求成功', value);
            return new Promise((resolve, reject) => {
                setTimeout(() => {
                    resolve('商品数据');
                }, 1000);
            });
        }).then(value => {
            console.log('第三次请求成功', value);
        }).catch(reason => {
            console.error(reason);
        });
        
    </script>
</body>
</html>